Workbook

Sheet Orig (V1_BCK)
A1: Coinciden con V1 | B1: Coinciden con V11 | D1: SGID | E1: Nombre | F1: Primer apellido | G1: Segundo apellido | H1: Unidad Org | I1: Nombre Unidad org | J1: SGID Resp Pos | K1: SGID Resp HR | L1: Unidad Org | M1: Nombre Resp Pos | N1: Nombre Resp HR | O1: Primer apellido Resp Pos | P1: Primer apellido Resp HR | Q1: Segundo apellido Resp Pos | R1: Segundo apellido Resp HR | S1: Record Type | T1: Box Sequence | U1: Empresa
A2: =INDEX('Correg (V1)'!$B:$B,MATCH($C2,'Correg (V1)'!$B:$B,0),1) -> A0702288-A0702288- | B2: =INDEX('Nueva (V11)'!$B:$B,MATCH($C2,'Nueva (V11)'!$B:$B,0),1) -> A0702288-A0702288- | C2: =_xlfn.TEXTJOIN("-",FALSE,$D2,$J2,$K2) -> A0702288-A0702288- | D2: A0702288 | E2: AITOR | F2: SANTIBAÑEZ | G2: RODRIGUEZ | H2: 01244 | I2: PRODUCCIÓN (01244) | J2: A0702288 | L2: 139250 | M2: AITOR | O2: SANTIBAÑEZ | Q2: RODRIGUEZ | U2: 58
A3: =INDEX('Correg (V1)'!$B:$B,MATCH($C3,'Correg (V1)'!$B:$B,0),1) -> A1137670--G3229318 | B3: =INDEX('Nueva (V11)'!$B:$B,MATCH($C3,'Nueva (V11)'!$B:$B,0),1) -> #N/A | C3: =_xlfn.TEXTJOIN("-",FALSE,$D3,$J3,$K3) -> A1137670--G3229318 | D3: A1137670 | E3: ANTONIO | F3: MARTINEZ | G3: ESCOLAR | H3: 03035 | I3: VENTAS (02283) | K3: G3229318 | L3: 01945 | N3: GREGORIO | P3: LASIERRA | R3: LAPLANA | U3: 83
A4: =INDEX('Correg (V1)'!$B:$B,MATCH($C4,'Correg (V1)'!$B:$B,0),1) -> A1692880-A1692880- | B4: =INDEX('Nueva (V11)'!$B:$B,MATCH($C4,'Nueva (V11)'!$B:$B,0),1) -> A1692880-A1692880- | C4: =_xlfn.TEXTJOIN("-",FALSE,$D4,$J4,$K4) -> A1692880-A1692880- | D4: A1692880 | E4: ANTONIO | F4: CORRALES | G4: PULIDO | H4: 01275 | I4: PRODUCCIÓN (01275) | J4: A1692880 | L4: 003175 | M4: ANTONIO | O4: CORRALES | Q4: PULIDO | U4: 2G
A5: =INDEX('Correg (V1)'!$B:$B,MATCH($C5,'Correg (V1)'!$B:$B,0),1) -> A1778775--I7600760 | B5: =INDEX('Nueva (V11)'!$B:$B,MATCH($C5,'Nueva (V11)'!$B:$B,0),1) -> #N/A | C5: =_xlfn.TEXTJOIN("-",FALSE,$D5,$J5,$K5) -> A1778775--I7600760 | D5: A1778775 | E5: ANTONIO | F5: GALVEZ | G5: GONZALEZ | H5: 04609 | I5: 04609 | K5: I7600760 | L5: 02425 | N5: ISMAEL | P5: CIVIT | R5: NOGUES | U5: 22
A6: =INDEX('Correg (V1)'!$B:$B,MATCH($C6,'Correg (V1)'!$B:$B,0),1) -> A1975872--J2161690 | B6: =INDEX('Nueva (V11)'!$B:$B,MATCH($C6,'Nueva (V11)'!$B:$B,0),1) -> A1975872--J2161690 | C6: =_xlfn.TEXTJOIN("-",FALSE,$D6,$J6,$K6) -> A1975872--J2161690 | D6: A1975872 | E6: ANGEL | F6: GONZALEZ | G6: DIAZ | H6: 00618 | I6: 00868 (COMPRADOR LOCAL) | K6: J2161690 | L6: 00868 | N6: JUAN CARLOS | P6: RODRIGUEZ | R6: ARMESTO | U6: 05
A7: =INDEX('Correg (V1)'!$B:$B,MATCH($C7,'Correg (V1)'!$B:$B,0),1) -> A2056971-A2056971- | B7: =INDEX('Nueva (V11)'!$B:$B,MATCH($C7,'Nueva (V11)'!$B:$B,0),1) -> #N/A | C7: =_xlfn.TEXTJOIN("-",FALSE,$D7,$J7,$K7) -> A2056971-A2056971- | D7: A2056971 | E7: ALBERTO | F7: ANTON | G7: ESCRIBANO | H7: 04309 | I7: PRODUCCIÓN (04309) | J7: A2056971 | L7: 145420 | M7: ALBERTO | O7: ANTON | Q7: ESCRIBANO | U7: 58
A8: =INDEX('Correg (V1)'!$B:$B,MATCH($C8,'Correg (V1)'!$B:$B,0),1) -> A2422013-A2422013- | B8: =INDEX('Nueva (V11)'!$B:$B,MATCH($C8,'Nueva (V11)'!$B:$B,0),1) -> A2422013-A2422013- | C8: =_xlfn.TEXTJOIN("-",FALSE,$D8,$J8,$K8) -> A2422013-A2422013- | D8: A2422013 | E8: ALVARO | F8: BARRIO | G8: DELGADO | H8: 01180 | I8: JEFE DE ÁREA (01180) | J8: A2422013 | L8: 002283 | M8: ALVARO | O8: BARRIO | Q8: DELGADO | U8: 22
A9: =INDEX('Correg (V1)'!$B:$B,MATCH($C9,'Correg (V1)'!$B:$B,0),1) -> A3127479-A3127479- | B9: =INDEX('Nueva (V11)'!$B:$B,MATCH($C9,'Nueva (V11)'!$B:$B,0),1) -> #N/A | C9: =_xlfn.TEXTJOIN("-",FALSE,$D9,$J9,$K9) -> A3127479-A3127479- | D9: A3127479 | E9: ALBERTO | F9: MARTINEZ | G9: CARRAL | H9: 04199 | I9: PRODUCCIÓN (04199) | J9: A3127479 | L9: 002123 | M9: ALBERTO | O9: MARTINEZ | Q9: CARRAL | U9: 71
A10: =INDEX('Correg (V1)'!$B:$B,MATCH($C10,'Correg (V1)'!$B:$B,0),1) -> A3167958-A3167958- | B10: =INDEX('Nueva (V11)'!$B:$B,MATCH($C10,'Nueva (V11)'!$B:$B,0),1) -> A3167958-A3167958- | C10: =_xlfn.TEXTJOIN("-",FALSE,$D10,$J10,$K10) -> A3167958-A3167958- | D10: A3167958 | E10: ANTONIO | F10: MORAL | G10: PEREZ | H10: 01730 | I10: JEFE DE ÁREA (01730) | J10: A3167958 | L10: 001778 | M10: ANTONIO | O10: MORAL | Q10: PEREZ | U10: 22
A11: =INDEX('Correg (V1)'!$B:$B,MATCH($C11,'Correg (V1)'!$B:$B,0),1) -> A3258905-A3258905- | B11: =INDEX('Nueva (V11)'!$B:$B,MATCH($C11,'Nueva (V11)'!$B:$B,0),1) -> A3258905-A3258905- | C11: =_xlfn.TEXTJOIN("-",FALSE,$D11,$J11,$K11) -> A3258905-A3258905- | D11: A3258905 | E11: ANGEL | F11: MARCILLA | G11: BASTIDA | H11: 02402 | I11: RESPONSABLE SERV FABRICACIÓN (02402) | J11: A3258905 | L11: 000601 | M11: ANGEL | O11: MARCILLA | Q11: BASTIDA | U11: 05
A12: =INDEX('Correg (V1)'!$B:$B,MATCH($C12,'Correg (V1)'!$B:$B,0),1) -> A3284599-A3284599- | B12: =INDEX('Nueva (V11)'!$B:$B,MATCH($C12,'Nueva (V11)'!$B:$B,0),1) -> #N/A | C12: =_xlfn.TEXTJOIN("-",FALSE,$D12,$J12,$K12) -> A3284599-A3284599- | D12: A3284599 | E12: ANGELICA | F12: GONZALO | G12: LOPEZ | H12: 03137 | I12: JEFE DE PRODUCTO (03137) | J12: A3284599 | L12: 000861 | M12: ANGELICA | O12: GONZALO | Q12: LOPEZ | U12: 58
A13: =INDEX('Correg (V1)'!$B:$B,MATCH($C13,'Correg (V1)'!$B:$B,0),1) -> A3417212-A3417212- | B13: =INDEX('Nueva (V11)'!$B:$B,MATCH($C13,'Nueva (V11)'!$B:$B,0),1) -> A3417212-A3417212- | C13: =_xlfn.TEXTJOIN("-",FALSE,$D13,$J13,$K13) -> A3417212-A3417212- | D13: A3417212 | E13: ALBERTO | F13: MARTINEZ | G13: DE PABLO | H13: 02437 | I13: RESPONSABLE LOGÍSTICA (02437) | J13: A3417212 | L13: 000701 | M13: ALBERTO | O13: MARTINEZ | Q13: DE PABLO | U13: 05
A14: =INDEX('Correg (V1)'!$B:$B,MATCH($C14,'Correg (V1)'!$B:$B,0),1) -> A3485213-A3485213- | B14: =INDEX('Nueva (V11)'!$B:$B,MATCH($C14,'Nueva (V11)'!$B:$B,0),1) -> A3485213-A3485213- | C14: =_xlfn.TEXTJOIN("-",FALSE,$D14,$J14,$K14) -> A3485213-A3485213- | D14: A3485213 | E14: AGUSTIN | F14: SUBIAS | G14: LIERTA | H14: 01589 | I14: PRODUCCIÓN (01589) | J14: A3485213 | L14: 139256 | M14: AGUSTIN | O14: SUBIAS | Q14: LIERTA | U14: 58
A15: =INDEX('Correg (V1)'!$B:$B,MATCH($C15,'Correg (V1)'!$B:$B,0),1) -> A3575764--J6399199 | B15: =INDEX('Nueva (V11)'!$B:$B,MATCH($C15,'Nueva (V11)'!$B:$B,0),1) -> #N/A | C15: =_xlfn.TEXTJOIN("-",FALSE,$D15,$J15,$K15) -> A3575764--J6399199 | D15: A3575764 | E15: ANTONIO | F15: VENDRELL | G15: VENDRELL | H15: 03363 | I15: SIN DEFINIR (03363) | K15: J6399199 | L15: 01878 | N15: JORDI | P15: ESTELLERS | R15: CASTELLVI | U15: 22
A16: =INDEX('Correg (V1)'!$B:$B,MATCH($C16,'Correg (V1)'!$B:$B,0),1) -> A4260911-A4260911- | B16: =INDEX('Nueva (V11)'!$B:$B,MATCH($C16,'Nueva (V11)'!$B:$B,0),1) -> #N/A | C16: =_xlfn.TEXTJOIN("-",FALSE,$D16,$J16,$K16) -> A4260911-A4260911- | D16: A4260911 | E16: ADOLFO | F16: SOMOLINOS | G16: OREJON | H16: 03429 | I16: RESPONSABLE DE ESTUDIOS MKG (03429) | J16: A4260911 | L16: 003330 | M16: ADOLFO | O16: SOMOLINOS | Q16: OREJON | U16: 58
A17: =INDEX('Correg (V1)'!$B:$B,MATCH($C17,'Correg (V1)'!$B:$B,0),1) -> A4544160--Y3223618 | B17: =INDEX('Nueva (V11)'!$B:$B,MATCH($C17,'Nueva (V11)'!$B:$B,0),1) -> A4544160--Y3223618 | C17: =_xlfn.TEXTJOIN("-",FALSE,$D17,$J17,$K17) -> A4544160--Y3223618 | D17: A4544160 | E17: ANTONIO | F17: TRUJILLO | G17: HELD | H17: 02480 | I17: 02480 | K17: Y3223618 | L17: 02655 | N17: YOLANDA | P17: PERALTA | R17: ROSALEN | U17: 22
A18: =INDEX('Correg (V1)'!$B:$B,MATCH($C18,'Correg (V1)'!$B:$B,0),1) -> #N/A | B18: =INDEX('Nueva (V11)'!$B:$B,MATCH($C18,'Nueva (V11)'!$B:$B,0),1) -> #N/A | C18: =_xlfn.TEXTJOIN("-",FALSE,$D18,$J18,$K18) -> A4598195-A4598195- | D18: A4598195 | E18: ALFREDO | F18: VILLA | G18: CELDRAN | H18: 02018 | I18: PRODUCCIÓN (02018) | J18: A4598195 | L18: 001429 | M18: ALFREDO | O18: VILLA | Q18: CELDRAN | U18: 05
A19: =INDEX('Correg (V1)'!$B:$B,MATCH($C19,'Correg (V1)'!$B:$B,0),1) -> A4769333--J1842217 | B19: =INDEX('Nueva (V11)'!$B:$B,MATCH($C19,'Nueva (V11)'!$B:$B,0),1) -> #N/A | C19: =_xlfn.TEXTJOIN("-",FALSE,$D19,$J19,$K19) -> A4769333--J1842217 | D19: A4769333 | E19: ALEJANDRO | F19: RUIZ | G19: DURAN | H19: 03045 | I19: 01317 (JEFE DE ÁREA) | K19: J1842217 | L19: 01317 | N19: JUAN CARLOS | P19: ARRIBAS | R19: RIAGUAS | U19: 22
A20: =INDEX('Correg (V1)'!$B:$B,MATCH($C20,'Correg (V1)'!$B:$B,0),1) -> #N/A | B20: =INDEX('Nueva (V11)'!$B:$B,MATCH($C20,'Nueva (V11)'!$B:$B,0),1) -> #N/A | C20: =_xlfn.TEXTJOIN("-",FALSE,$D20,$J20,$K20) -> A5336853-A5336853- | D20: A5336853 | E20: ANTONIO | F20: PONSODA | G20: REINA | H20: 00242 | I20: PRODUCCIÓN (00242) | J20: A5336853 | L20: 001685 | M20: ANTONIO | O20: PONSODA | Q20: REINA | U20: 2G
A21: =INDEX('Correg (V1)'!$B:$B,MATCH($C21,'Correg (V1)'!$B:$B,0),1) -> A5358571-A5358571- | B21: =INDEX('Nueva (V11)'!$B:$B,MATCH($C21,'Nueva (V11)'!$B:$B,0),1) -> #N/A | C21: =_xlfn.TEXTJOIN("-",FALSE,$D21,$J21,$K21) -> A5358571-A5358571- | D21: A5358571 | E21: ADRIAN | F21: PALACIO | G21: BEDIA | H21: 04193 | I21: PRODUCCIÓN (04193) | J21: A5358571 | L21: 002083 | M21: ADRIAN | O21: PALACIO | Q21: BEDIA | U21: 71
A22: =INDEX('Correg (V1)'!$B:$B,MATCH($C22,'Correg (V1)'!$B:$B,0),1) -> A5709653-A5709653- | B22: =INDEX('Nueva (V11)'!$B:$B,MATCH($C22,'Nueva (V11)'!$B:$B,0),1) -> #N/A | C22: =_xlfn.TEXTJOIN("-",FALSE,$D22,$J22,$K22) -> A5709653-A5709653- | D22: A5709653 | E22: ANTONIO | F22: OLMO | G22: MELGAR | H22: 03407 | I22: PRODUCCIÓN (03407) | J22: A5709653 | L22: 139187 | M22: ANTONIO | O22: OLMO | Q22: MELGAR | U22: 58
A23: =INDEX('Correg (V1)'!$B:$B,MATCH($C23,'Correg (V1)'!$B:$B,0),1) -> A6553191--F7796330 | B23: =INDEX('Nueva (V11)'!$B:$B,MATCH($C23,'Nueva (V11)'!$B:$B,0),1) -> #N/A | C23: =_xlfn.TEXTJOIN("-",FALSE,$D23,$J23,$K23) -> A6553191--F7796330 | D23: A6553191 | E23: ANTONIO M. | F23: DE LA FUENTE | G23: GUTIERREZ | H23: 04219 | I23: PRODUCCIÓN (04219) | K23: F7796330 | L23: 01040 | N23: FRANCISCO JAVIER | P23: BRAVO | R23: SARO | U23: 71
A24: =INDEX('Correg (V1)'!$B:$B,MATCH($C24,'Correg (V1)'!$B:$B,0),1) -> A6556153-A6556153- | B24: =INDEX('Nueva (V11)'!$B:$B,MATCH($C24,'Nueva (V11)'!$B:$B,0),1) -> #N/A | C24: =_xlfn.TEXTJOIN("-",FALSE,$D24,$J24,$K24) -> A6556153-A6556153- | D24: A6556153 | E24: ANTONIO MOISES | F24: SANTOS | G24: AVELLANO | H24: 03662 | I24: OPERACIONES DISTRIBUCIÓN (03363) | J24: A6556153 | L24: 002583 | M24: ANTONIO MOISES | O24: SANTOS | Q24: AVELLANO | U24: 62
A25: =INDEX('Correg (V1)'!$B:$B,MATCH($C25,'Correg (V1)'!$B:$B,0),1) -> A6653585-A6653585- | B25: =INDEX('Nueva (V11)'!$B:$B,MATCH($C25,'Nueva (V11)'!$B:$B,0),1) -> A6653585-A6653585- | C25: =_xlfn.TEXTJOIN("-",FALSE,$D25,$J25,$K25) -> A6653585-A6653585- | D25: A6653585 | E25: ANTONIO | F25: LUNA | G25: LIBRERO | H25: 01662 | I25: DIRECTOR DE FÁBRICA (01662) | J25: A6653585 | L25: 000950 | M25: ANTONIO | O25: LUNA | Q25: LIBRERO | U25: 58
A26: =INDEX('Correg (V1)'!$B:$B,MATCH($C26,'Correg (V1)'!$B:$B,0),1) -> A6687307--R3817235 | B26: =INDEX('Nueva (V11)'!$B:$B,MATCH($C26,'Nueva (V11)'!$B:$B,0),1) -> A6687307--R3817235 | C26: =_xlfn.TEXTJOIN("-",FALSE,$D26,$J26,$K26) -> A6687307--R3817235 | D26: A6687307 | E26: ANTONIO | F26: MONTES | G26: SANCHEZ | H26: 02834 | I26: DIRECTOR LOGÍSTICA (02834) | K26: R3817235 | L26: 01362 | N26: RAUL GASPAR | P26: MONTAÑES | R26: TORRENT | U26: 22
A27: =INDEX('Correg (V1)'!$B:$B,MATCH($C27,'Correg (V1)'!$B:$B,0),1) -> A7005471--J6399199 | B27: =INDEX('Nueva (V11)'!$B:$B,MATCH($C27,'Nueva (V11)'!$B:$B,0),1) -> A7005471--J6399199 | C27: =_xlfn.TEXTJOIN("-",FALSE,$D27,$J27,$K27) -> A7005471--J6399199 | D27: A7005471 | E27: ANA MARTA | F27: SANCHEZ | G27: FERNANDEZ | H27: 01883 | I27: SIN DEFINIR (01700) | K27: J6399199 | L27: 01878 | N27: JORDI | P27: ESTELLERS | R27: CASTELLVI | U27: 22
A28: =INDEX('Correg (V1)'!$B:$B,MATCH($C28,'Correg (V1)'!$B:$B,0),1) -> A7527556--A2422013 | B28: =INDEX('Nueva (V11)'!$B:$B,MATCH($C28,'Nueva (V11)'!$B:$B,0),1) -> #N/A | C28: =_xlfn.TEXTJOIN("-",FALSE,$D28,$J28,$K28) -> A7527556--A2422013 | D28: A7527556 | E28: ANASTASIO | F28: MARTIN GIL | G28: ROMERO HOMBREBU | H28: 03439 | I28: SIN DEFINIR (03439) | K28: A2422013 | L28: 01180 | N28: ALVARO | P28: BARRIO | R28: DELGADO | U28: 22
A29: =INDEX('Correg (V1)'!$B:$B,MATCH($C29,'Correg (V1)'!$B:$B,0),1) -> A8353376--M3569866 | B29: =INDEX('Nueva (V11)'!$B:$B,MATCH($C29,'Nueva (V11)'!$B:$B,0),1) -> A8353376--M3569866 | C29: =_xlfn.TEXTJOIN("-",FALSE,$D29,$J29,$K29) -> A8353376--M3569866 | D29: A8353376 | E29: AGUSTIN | F29: ESCOBAR | G29: SERRANO | H29: 00045 | I29: PRODUCCIÓN (00045) | K29: M3569866 | L29: 03546 | N29: MIRIAM | P29: SIERRA | R29: RODRIGUEZ | U29: 58
A30: =INDEX('Correg (V1)'!$B:$B,MATCH($C30,'Correg (V1)'!$B:$B,0),1) -> A8361287--I8301604 | B30: =INDEX('Nueva (V11)'!$B:$B,MATCH($C30,'Nueva (V11)'!$B:$B,0),1) -> #N/A | C30: =_xlfn.TEXTJOIN("-",FALSE,$D30,$J30,$K30) -> A8361287--I8301604 | D30: A8361287 | E30: ALEJANDRO | F30: GARCIA | G30: JIMENEZ | H30: 02901 | I30: PRODUCCIÓN (02901) | K30: I8301604 | L30: 00248 | N30: IVAN | P30: FERNANDEZ | R30: RODRIGUEZ | U30: 58
A31: =INDEX('Correg (V1)'!$B:$B,MATCH($C31,'Correg (V1)'!$B:$B,0),1) -> A9859396--J6399199 | B31: =INDEX('Nueva (V11)'!$B:$B,MATCH($C31,'Nueva (V11)'!$B:$B,0),1) -> A9859396--J6399199 | C31: =_xlfn.TEXTJOIN("-",FALSE,$D31,$J31,$K31) -> A9859396--J6399199 | D31: A9859396 | E31: ANA ISABEL | F31: MITJAVILA | G31: ESCUDERO | H31: 02641 | I31: SIN DEFINIR (02641) | K31: J6399199 | L31: 01878 | N31: JORDI | P31: ESTELLERS | R31: CASTELLVI | U31: 22
A32: =INDEX('Correg (V1)'!$B:$B,MATCH($C32,'Correg (V1)'!$B:$B,0),1) -> A9899465-A9899465- | B32: =INDEX('Nueva (V11)'!$B:$B,MATCH($C32,'Nueva (V11)'!$B:$B,0),1) -> #N/A | C32: =_xlfn.TEXTJOIN("-",FALSE,$D32,$J32,$K32) -> A9899465-A9899465- | D32: A9899465 | E32: ALBERTO | F32: GUTIERREZ | G32: GARCIA | H32: 04231 | I32: PRODUCCIÓN (04231) | J32: A9899465 | L32: 144089 | M32: ALBERTO | O32: GUTIERREZ | Q32: GARCIA | U32: 71
A33: =INDEX('Correg (V1)'!$B:$B,MATCH($C33,'Correg (V1)'!$B:$B,0),1) -> B4736339-B4736339- | B33: =INDEX('Nueva (V11)'!$B:$B,MATCH($C33,'Nueva (V11)'!$B:$B,0),1) -> #N/A | C33: =_xlfn.TEXTJOIN("-",FALSE,$D33,$J33,$K33) -> B4736339-B4736339- | D33: B4736339 | E33: BLANCA LUNA | F33: CORRAL | G33: CORDERO | H33: 03858 | I33: VENTAS (03858) | J33: B4736339 | L33: 003157 | M33: BLANCA LUNA | O33: CORRAL | Q33: CORDERO | U33: 62
A34: =INDEX('Correg (V1)'!$B:$B,MATCH($C34,'Correg (V1)'!$B:$B,0),1) -> C0100439-C0100439- | B34: =INDEX('Nueva (V11)'!$B:$B,MATCH($C34,'Nueva (V11)'!$B:$B,0),1) -> C0100439-C0100439- | C34: =_xlfn.TEXTJOIN("-",FALSE,$D34,$J34,$K34) -> C0100439-C0100439- | D34: C0100439 | E34: CESAR | F34: RAMOS | G34: MORAN | H34: 00599 | I34: PRODUCCIÓN (00599) | J34: C0100439 | L34: 003225 | M34: CESAR | O34: RAMOS | Q34: MORAN | U34: 2G
A35: =INDEX('Correg (V1)'!$B:$B,MATCH($C35,'Correg (V1)'!$B:$B,0),1) -> C7169588-C7169588- | B35: =INDEX('Nueva (V11)'!$B:$B,MATCH($C35,'Nueva (V11)'!$B:$B,0),1) -> C7169588-C7169588- | C35: =_xlfn.TEXTJOIN("-",FALSE,$D35,$J35,$K35) -> C7169588-C7169588- | D35: C7169588 | E35: CARLOS | F35: RODRIGUEZ | G35: GARCIA | H35: 02771 | I35: JEFE VENTAS - OPERACIÓN DISTR (02771) | J35: C7169588 | L35: 003972 | M35: CARLOS | O35: RODRIGUEZ | Q35: GARCIA | U35: 62
A36: =INDEX('Correg (V1)'!$B:$B,MATCH($C36,'Correg (V1)'!$B:$B,0),1) -> C9446654--J6399199 | B36: =INDEX('Nueva (V11)'!$B:$B,MATCH($C36,'Nueva (V11)'!$B:$B,0),1) -> C9446654--J6399199 | C36: =_xlfn.TEXTJOIN("-",FALSE,$D36,$J36,$K36) -> C9446654--J6399199 | D36: C9446654 | E36: CHRISTIAN FRANC | F36: ESCUDERO | G36: DOMENECH | H36: 02283 | I36: SIN DEFINIR (02283) | K36: J6399199 | L36: 01878 | N36: JORDI | P36: ESTELLERS | R36: CASTELLVI | U36: 22
A37: =INDEX('Correg (V1)'!$B:$B,MATCH($C37,'Correg (V1)'!$B:$B,0),1) -> C9612177-C9612177- | B37: =INDEX('Nueva (V11)'!$B:$B,MATCH($C37,'Nueva (V11)'!$B:$B,0),1) -> C9612177-C9612177- | C37: =_xlfn.TEXTJOIN("-",FALSE,$D37,$J37,$K37) -> C9612177-C9612177- | D37: C9612177 | E37: CARLOS | F37: BRIS | G37: CABRERIZO | H37: 00159 | I37: RESPONSABLE MANTENIMIENTO (00159) | J37: C9612177 | L37: 002363 | M37: CARLOS | O37: BRIS | Q37: CABRERIZO | U37: 2G
A38: =INDEX('Correg (V1)'!$B:$B,MATCH($C38,'Correg (V1)'!$B:$B,0),1) -> D0530111-D0530111- | B38: =INDEX('Nueva (V11)'!$B:$B,MATCH($C38,'Nueva (V11)'!$B:$B,0),1) -> D0530111-D0530111- | C38: =_xlfn.TEXTJOIN("-",FALSE,$D38,$J38,$K38) -> D0530111-D0530111- | D38: D0530111 | E38: DAVID | F38: DE BENITO | G38: MIGUEL | H38: 00362 | I38: LOGÍSTICA (00362) | J38: D0530111 | L38: 141171 | M38: DAVID | O38: DE BENITO | Q38: MIGUEL | U38: 71
A39: =INDEX('Correg (V1)'!$B:$B,MATCH($C39,'Correg (V1)'!$B:$B,0),1) -> D0601716--F6446981 | B39: =INDEX('Nueva (V11)'!$B:$B,MATCH($C39,'Nueva (V11)'!$B:$B,0),1) -> #N/A | C39: =_xlfn.TEXTJOIN("-",FALSE,$D39,$J39,$K39) -> D0601716--F6446981 | D39: D0601716 | E39: DANIEL | F39: GUTIERREZ | G39: TOLEDO | H39: 04639 | I39: 04639 | K39: F6446981 | L39: 01466 | N39: FRANCISCO JOSE | P39: NAVARRO | R39: CEBRIAN | U39: 22
A40: =INDEX('Correg (V1)'!$B:$B,MATCH($C40,'Correg (V1)'!$B:$B,0),1) -> D2301615-D2301615- | B40: =INDEX('Nueva (V11)'!$B:$B,MATCH($C40,'Nueva (V11)'!$B:$B,0),1) -> #N/A | C40: =_xlfn.TEXTJOIN("-",FALSE,$D40,$J40,$K40) -> D2301615-D2301615- | D40: D2301615 | E40: DAVID | F40: GONZALEZ | G40: CALDERON | H40: 03954 | I40: PRODUCCIÓN (03954) | J40: D2301615 | L40: 004200 | M40: DAVID | O40: GONZALEZ | Q40: CALDERON | U40: 58
...

Sheet Nueva (V11)
A1: Coinciden con V1_BCK | C1: SGID | D1: Nombre | E1: Primer apellido | F1: Segundo apellido | G1: Unidad Org | H1: Nombre Unidad org | I1: SGID Resp Pos | J1: SGID Resp HR | K1: Unidad Org | L1: Nombre Resp Pos | M1: Nombre Resp HR | N1: Primer apellido Resp Pos | O1: Primer apellido Resp HR | P1: Segundo apellido Resp Pos | Q1: Segundo apellido Resp HR | R1: Record Type | S1: Box Sequence | T1: Empresa
A2: =INDEX('Orig (V1_BCK)'!$C:$C,MATCH($B2,'Orig (V1_BCK)'!$C:$C,0),1) -> A0702288-A0702288- | B2: =_xlfn.TEXTJOIN("-",FALSE,$C2,$I2,$J2) -> A0702288-A0702288- | C2: A0702288 | D2: AITOR | E2: SANTIBAÑEZ | F2: RODRIGUEZ | G2: 01244 | H2: PRODUCCIÓN (01244) | I2: A0702288 | K2: 139250 | L2: AITOR | N2: SANTIBAÑEZ | P2: RODRIGUEZ | T2: 58
A3: =INDEX('Orig (V1_BCK)'!$C:$C,MATCH($B3,'Orig (V1_BCK)'!$C:$C,0),1) -> A1692880-A1692880- | B3: =_xlfn.TEXTJOIN("-",FALSE,$C3,$I3,$J3) -> A1692880-A1692880- | C3: A1692880 | D3: ANTONIO | E3: CORRALES | F3: PULIDO | G3: 01275 | H3: PRODUCCIÓN (01275) | I3: A1692880 | K3: 003175 | L3: ANTONIO | N3: CORRALES | P3: PULIDO | T3: 2G
A4: =INDEX('Orig (V1_BCK)'!$C:$C,MATCH($B4,'Orig (V1_BCK)'!$C:$C,0),1) -> A1975872--J2161690 | B4: =_xlfn.TEXTJOIN("-",FALSE,$C4,$I4,$J4) -> A1975872--J2161690 | C4: A1975872 | D4: ANGEL | E4: GONZALEZ | F4: DIAZ | G4: 00618 | H4: 00868 (COMPRADOR LOCAL) | J4: J2161690 | K4: 00868 | M4: JUAN CARLOS | O4: RODRIGUEZ | Q4: ARMESTO | T4: 05
A5: =INDEX('Orig (V1_BCK)'!$C:$C,MATCH($B5,'Orig (V1_BCK)'!$C:$C,0),1) -> A2422013-A2422013- | B5: =_xlfn.TEXTJOIN("-",FALSE,$C5,$I5,$J5) -> A2422013-A2422013- | C5: A2422013 | D5: ALVARO | E5: BARRIO | F5: DELGADO | G5: 01180 | H5: JEFE DE ÁREA (01180) | I5: A2422013 | K5: 002283 | L5: ALVARO | N5: BARRIO | P5: DELGADO | T5: 22
A6: =INDEX('Orig (V1_BCK)'!$C:$C,MATCH($B6,'Orig (V1_BCK)'!$C:$C,0),1) -> A3167958-A3167958- | B6: =_xlfn.TEXTJOIN("-",FALSE,$C6,$I6,$J6) -> A3167958-A3167958- | C6: A3167958 | D6: ANTONIO | E6: MORAL | F6: PEREZ | G6: 01730 | H6: JEFE DE ÁREA (01730) | I6: A3167958 | K6: 001778 | L6: ANTONIO | N6: MORAL | P6: PEREZ | T6: 22
A7: =INDEX('Orig (V1_BCK)'!$C:$C,MATCH($B7,'Orig (V1_BCK)'!$C:$C,0),1) -> A3258905-A3258905- | B7: =_xlfn.TEXTJOIN("-",FALSE,$C7,$I7,$J7) -> A3258905-A3258905- | C7: A3258905 | D7: ANGEL | E7: MARCILLA | F7: BASTIDA | G7: 02402 | H7: RESPONSABLE SERV FABRICACIÓN (02402) | I7: A3258905 | K7: 000601 | L7: ANGEL | N7: MARCILLA | P7: BASTIDA | T7: 05
A8: =INDEX('Orig (V1_BCK)'!$C:$C,MATCH($B8,'Orig (V1_BCK)'!$C:$C,0),1) -> A3417212-A3417212- | B8: =_xlfn.TEXTJOIN("-",FALSE,$C8,$I8,$J8) -> A3417212-A3417212- | C8: A3417212 | D8: ALBERTO | E8: MARTINEZ | F8: DE PABLO | G8: 02437 | H8: RESPONSABLE LOGÍSTICA (02437) | I8: A3417212 | K8: 000701 | L8: ALBERTO | N8: MARTINEZ | P8: DE PABLO | T8: 05
A9: =INDEX('Orig (V1_BCK)'!$C:$C,MATCH($B9,'Orig (V1_BCK)'!$C:$C,0),1) -> A3485213-A3485213- | B9: =_xlfn.TEXTJOIN("-",FALSE,$C9,$I9,$J9) -> A3485213-A3485213- | C9: A3485213 | D9: AGUSTIN | E9: SUBIAS | F9: LIERTA | G9: 01589 | H9: PRODUCCIÓN (01589) | I9: A3485213 | K9: 139256 | L9: AGUSTIN | N9: SUBIAS | P9: LIERTA | T9: 58
A10: =INDEX('Orig (V1_BCK)'!$C:$C,MATCH($B10,'Orig (V1_BCK)'!$C:$C,0),1) -> A4544160--Y3223618 | B10: =_xlfn.TEXTJOIN("-",FALSE,$C10,$I10,$J10) -> A4544160--Y3223618 | C10: A4544160 | D10: ANTONIO | E10: TRUJILLO | F10: HELD | G10: 02480 | H10: 02480 | J10: Y3223618 | K10: 02655 | M10: YOLANDA | O10: PERALTA | Q10: ROSALEN | T10: 22
A11: =INDEX('Orig (V1_BCK)'!$C:$C,MATCH($B11,'Orig (V1_BCK)'!$C:$C,0),1) -> #N/A | B11: =_xlfn.TEXTJOIN("-",FALSE,$C11,$I11,$J11) -> A4598195-- | C11: A4598195 | D11: ALFREDO | E11: VILLA | F11: CELDRAN | G11: 02018 | H11: PRODUCCIÓN (02018) | K11: 001429 | T11: 05
A12: =INDEX('Orig (V1_BCK)'!$C:$C,MATCH($B12,'Orig (V1_BCK)'!$C:$C,0),1) -> #N/A | B12: =_xlfn.TEXTJOIN("-",FALSE,$C12,$I12,$J12) -> A5205505-- | C12: A5205505 | D12: ANTONIO JESUS | E12: MUÑOZ | F12: DEL ARCO | G12: 001048 | H12: MD SG PAM SPAIN & PORTUGAL | K12: 001864 | T12: 1J
A13: =INDEX('Orig (V1_BCK)'!$C:$C,MATCH($B13,'Orig (V1_BCK)'!$C:$C,0),1) -> #N/A | B13: =_xlfn.TEXTJOIN("-",FALSE,$C13,$I13,$J13) -> A5336853-- | C13: A5336853 | D13: ANTONIO | E13: PONSODA | F13: REINA | G13: 00242 | H13: PRODUCCIÓN (00242) | K13: 001685 | T13: 2G
A14: =INDEX('Orig (V1_BCK)'!$C:$C,MATCH($B14,'Orig (V1_BCK)'!$C:$C,0),1) -> #N/A | B14: =_xlfn.TEXTJOIN("-",FALSE,$C14,$I14,$J14) -> A6363564-J0041893- | C14: A6363564 | D14: ANA ISABEL | E14: LEON | F14: CASTAÑO | G14: 000077 | H14: LEGAL DIRECTOR& REAL ESTATE MANAGER | I14: J0041893 | K14: 002483 | L14: JEAN LUC | N14: GARDAZ | P14: . | T14: 1J
A15: =INDEX('Orig (V1_BCK)'!$C:$C,MATCH($B15,'Orig (V1_BCK)'!$C:$C,0),1) -> #N/A | B15: =_xlfn.TEXTJOIN("-",FALSE,$C15,$I15,$J15) -> A6363564-J0041893- | C15: A6363564 | D15: ANA ISABEL | E15: LEON | F15: CASTAÑO | G15: 002664 | H15: PURCHASING DIRECTOR E-P-M-A-I-G | I15: J0041893 | K15: 002483 | L15: JEAN LUC | N15: GARDAZ | P15: . | T15: 1J
A16: =INDEX('Orig (V1_BCK)'!$C:$C,MATCH($B16,'Orig (V1_BCK)'!$C:$C,0),1) -> #N/A | B16: =_xlfn.TEXTJOIN("-",FALSE,$C16,$I16,$J16) -> A6363564-J0041893- | C16: A6363564 | D16: ANA ISABEL | E16: LEON | F16: CASTAÑO | G16: 002850 | H16: HRD SPAIN, PORTUGAL, MOROCCO & ALGERIA | I16: J0041893 | K16: 002483 | L16: JEAN LUC | N16: GARDAZ | P16: . | T16: 1J
A17: =INDEX('Orig (V1_BCK)'!$C:$C,MATCH($B17,'Orig (V1_BCK)'!$C:$C,0),1) -> #N/A | B17: =_xlfn.TEXTJOIN("-",FALSE,$C17,$I17,$J17) -> A6363564-J0041893- | C17: A6363564 | D17: ANA ISABEL | E17: LEON | F17: CASTAÑO | G17: 003263 | H17: CFO SPAIN PORTUGAL & MOROCCO | I17: J0041893 | K17: 002483 | L17: JEAN LUC | N17: GARDAZ | P17: . | T17: 1J
A18: =INDEX('Orig (V1_BCK)'!$C:$C,MATCH($B18,'Orig (V1_BCK)'!$C:$C,0),1) -> A6653585-A6653585- | B18: =_xlfn.TEXTJOIN("-",FALSE,$C18,$I18,$J18) -> A6653585-A6653585- | C18: A6653585 | D18: ANTONIO | E18: LUNA | F18: LIBRERO | G18: 01662 | H18: DIRECTOR DE FÁBRICA (01662) | I18: A6653585 | K18: 000950 | L18: ANTONIO | N18: LUNA | P18: LIBRERO | T18: 58
A19: =INDEX('Orig (V1_BCK)'!$C:$C,MATCH($B19,'Orig (V1_BCK)'!$C:$C,0),1) -> A6687307--R3817235 | B19: =_xlfn.TEXTJOIN("-",FALSE,$C19,$I19,$J19) -> A6687307--R3817235 | C19: A6687307 | D19: ANTONIO | E19: MONTES | F19: SANCHEZ | G19: 02834 | H19: DIRECTOR LOGÍSTICA (02834) | J19: R3817235 | K19: 01362 | M19: RAUL GASPAR | O19: MONTAÑES | Q19: TORRENT | T19: 22
A20: =INDEX('Orig (V1_BCK)'!$C:$C,MATCH($B20,'Orig (V1_BCK)'!$C:$C,0),1) -> A7005471--J6399199 | B20: =_xlfn.TEXTJOIN("-",FALSE,$C20,$I20,$J20) -> A7005471--J6399199 | C20: A7005471 | D20: ANA MARTA | E20: SANCHEZ | F20: FERNANDEZ | G20: 01883 | H20: SIN DEFINIR (01700) | J20: J6399199 | K20: 01878 | M20: JORDI | O20: ESTELLERS | Q20: CASTELLVI | T20: 22
A21: =INDEX('Orig (V1_BCK)'!$C:$C,MATCH($B21,'Orig (V1_BCK)'!$C:$C,0),1) -> A8353376--M3569866 | B21: =_xlfn.TEXTJOIN("-",FALSE,$C21,$I21,$J21) -> A8353376--M3569866 | C21: A8353376 | D21: AGUSTIN | E21: ESCOBAR | F21: SERRANO | G21: 00045 | H21: PRODUCCIÓN (00045) | J21: M3569866 | K21: 03546 | M21: MIRIAM | O21: SIERRA | Q21: RODRIGUEZ | T21: 58
A22: =INDEX('Orig (V1_BCK)'!$C:$C,MATCH($B22,'Orig (V1_BCK)'!$C:$C,0),1) -> A9859396--J6399199 | B22: =_xlfn.TEXTJOIN("-",FALSE,$C22,$I22,$J22) -> A9859396--J6399199 | C22: A9859396 | D22: ANA ISABEL | E22: MITJAVILA | F22: ESCUDERO | G22: 02641 | H22: SIN DEFINIR (02641) | J22: J6399199 | K22: 01878 | M22: JORDI | O22: ESTELLERS | Q22: CASTELLVI | T22: 22
A23: =INDEX('Orig (V1_BCK)'!$C:$C,MATCH($B23,'Orig (V1_BCK)'!$C:$C,0),1) -> #N/A | B23: =_xlfn.TEXTJOIN("-",FALSE,$C23,$I23,$J23) -> B9324934-- | C23: B9324934 | D23: BLANCA | E23: MARTIN | F23: GONZALEZ | G23: 001138 | H23: MD SG AUTOVER ESPAÑA | K23: 001863 | T23: 76
A24: =INDEX('Orig (V1_BCK)'!$C:$C,MATCH($B24,'Orig (V1_BCK)'!$C:$C,0),1) -> C0100439-C0100439- | B24: =_xlfn.TEXTJOIN("-",FALSE,$C24,$I24,$J24) -> C0100439-C0100439- | C24: C0100439 | D24: CESAR | E24: RAMOS | F24: MORAN | G24: 00599 | H24: PRODUCCIÓN (00599) | I24: C0100439 | K24: 003225 | L24: CESAR | N24: RAMOS | P24: MORAN | T24: 2G
A25: =INDEX('Orig (V1_BCK)'!$C:$C,MATCH($B25,'Orig (V1_BCK)'!$C:$C,0),1) -> #N/A | B25: =_xlfn.TEXTJOIN("-",FALSE,$C25,$I25,$J25) -> C3084002-J5768651- | C25: C3084002 | D25: CRISTINA | E25: PALOMARES | F25: MARTIN | G25: 000584 | H25: AVILES PLANT MANAGER SGS | I25: J5768651 | K25: 000006 | L25: JOSE ANTONIO | N25: PIQUERAS | P25: DIAZ PERONA | T25: 1J
A26: =INDEX('Orig (V1_BCK)'!$C:$C,MATCH($B26,'Orig (V1_BCK)'!$C:$C,0),1) -> #N/A | B26: =_xlfn.TEXTJOIN("-",FALSE,$C26,$I26,$J26) -> C6644203-J5768651- | C26: C6644203 | D26: CARMEN | E26: PEREZ | F26: FERNANDEZ-CABALLERO | G26: 000586 | H26: ARBOS PLANT MANAGER SGS & DEVISA MGR | I26: J5768651 | K26: 000006 | L26: JOSE ANTONIO | N26: PIQUERAS | P26: DIAZ PERONA | T26: 1J
A27: =INDEX('Orig (V1_BCK)'!$C:$C,MATCH($B27,'Orig (V1_BCK)'!$C:$C,0),1) -> C7169588-C7169588- | B27: =_xlfn.TEXTJOIN("-",FALSE,$C27,$I27,$J27) -> C7169588-C7169588- | C27: C7169588 | D27: CARLOS | E27: RODRIGUEZ | F27: GARCIA | G27: 02771 | H27: JEFE VENTAS - OPERACIÓN DISTR (02771) | I27: C7169588 | K27: 003972 | L27: CARLOS | N27: RODRIGUEZ | P27: GARCIA | T27: 62
A28: =INDEX('Orig (V1_BCK)'!$C:$C,MATCH($B28,'Orig (V1_BCK)'!$C:$C,0),1) -> C9446654--J6399199 | B28: =_xlfn.TEXTJOIN("-",FALSE,$C28,$I28,$J28) -> C9446654--J6399199 | C28: C9446654 | D28: CHRISTIAN FRANC | E28: ESCUDERO | F28: DOMENECH | G28: 02283 | H28: SIN DEFINIR (02283) | J28: J6399199 | K28: 01878 | M28: JORDI | O28: ESTELLERS | Q28: CASTELLVI | T28: 22
A29: =INDEX('Orig (V1_BCK)'!$C:$C,MATCH($B29,'Orig (V1_BCK)'!$C:$C,0),1) -> C9612177-C9612177- | B29: =_xlfn.TEXTJOIN("-",FALSE,$C29,$I29,$J29) -> C9612177-C9612177- | C29: C9612177 | D29: CARLOS | E29: BRIS | F29: CABRERIZO | G29: 00159 | H29: RESPONSABLE MANTENIMIENTO (00159) | I29: C9612177 | K29: 002363 | L29: CARLOS | N29: BRIS | P29: CABRERIZO | T29: 2G
A30: =INDEX('Orig (V1_BCK)'!$C:$C,MATCH($B30,'Orig (V1_BCK)'!$C:$C,0),1) -> D0530111-D0530111- | B30: =_xlfn.TEXTJOIN("-",FALSE,$C30,$I30,$J30) -> D0530111-D0530111- | C30: D0530111 | D30: DAVID | E30: DE BENITO | F30: MIGUEL | G30: 00362 | H30: LOGÍSTICA (00362) | I30: D0530111 | K30: 141171 | L30: DAVID | N30: DE BENITO | P30: MIGUEL | T30: 71
A31: =INDEX('Orig (V1_BCK)'!$C:$C,MATCH($B31,'Orig (V1_BCK)'!$C:$C,0),1) -> #N/A | B31: =_xlfn.TEXTJOIN("-",FALSE,$C31,$I31,$J31) -> D3115430-B4939781- | C31: D3115430 | D31: DAVID | E31: SILGADO | F31: MORENA | G31: 001804 | H31: CUSTOMER SERV.&PRICING ANALYSIS MGR UPSTREAM BG SP | I31: B4939781 | K31: 001798 | L31: BEATRIZ | N31: SIRVENT | P31: LUNA | T31: 27
A32: =INDEX('Orig (V1_BCK)'!$C:$C,MATCH($B32,'Orig (V1_BCK)'!$C:$C,0),1) -> D5004487--A3575764 | B32: =_xlfn.TEXTJOIN("-",FALSE,$C32,$I32,$J32) -> D5004487--A3575764 | C32: D5004487 | D32: DAVID | E32: LARROSA | F32: CANO | G32: 01562 | H32: 01562 | J32: A3575764 | K32: 03363 | M32: ANTONIO | O32: VENDRELL | Q32: VENDRELL | T32: 22
A33: =INDEX('Orig (V1_BCK)'!$C:$C,MATCH($B33,'Orig (V1_BCK)'!$C:$C,0),1) -> D6725163--J5549918 | B33: =_xlfn.TEXTJOIN("-",FALSE,$C33,$I33,$J33) -> D6725163--J5549918 | C33: D6725163 | D33: DAVID | E33: OLIVAR | F33: DOMINGUEZ | G33: 00550 | H33: 00935 (JEFE VENTAS - OPERACIÓN DISTR) | J33: J5549918 | K33: 00935 | M33: JAVIER | O33: MUÑIZ | Q33: MIGUELEZ | T33: 22
A34: =INDEX('Orig (V1_BCK)'!$C:$C,MATCH($B34,'Orig (V1_BCK)'!$C:$C,0),1) -> D8102953--A3167958 | B34: =_xlfn.TEXTJOIN("-",FALSE,$C34,$I34,$J34) -> D8102953--A3167958 | C34: D8102953 | D34: DANIEL | E34: GALAN | F34: AGUNDEZ | G34: 01681 | H34: 01681 | J34: A3167958 | K34: 01730 | M34: ANTONIO | O34: MORAL | Q34: PEREZ | T34: 22
A35: =INDEX('Orig (V1_BCK)'!$C:$C,MATCH($B35,'Orig (V1_BCK)'!$C:$C,0),1) -> D8399181-D8399181- | B35: =_xlfn.TEXTJOIN("-",FALSE,$C35,$I35,$J35) -> D8399181-D8399181- | C35: D8399181 | D35: DAVID | E35: DEL AMO | F35: BRAVO | G35: 01299 | H35: RESPONSABLE MANTENIMIENTO (01299) | I35: D8399181 | K35: 004290 | L35: DAVID | N35: DEL AMO | P35: BRAVO | T35: 58
A36: =INDEX('Orig (V1_BCK)'!$C:$C,MATCH($B36,'Orig (V1_BCK)'!$C:$C,0),1) -> E3234664--J2543295 | B36: =_xlfn.TEXTJOIN("-",FALSE,$C36,$I36,$J36) -> E3234664--J2543295 | C36: E3234664 | D36: ESTHER | E36: PRAT | F36: GIL | G36: 02673 | H36: DIRECTOR I+D (02673) | J36: J2543295 | K36: 03523 | M36: JORGE VICENTE | O36: RIUS | Q36: PUIG | T36: 83
A37: =INDEX('Orig (V1_BCK)'!$C:$C,MATCH($B37,'Orig (V1_BCK)'!$C:$C,0),1) -> #N/A | B37: =_xlfn.TEXTJOIN("-",FALSE,$C37,$I37,$J37) -> E3965521-J0041893- | C37: E3965521 | D37: EVA MARIA | E37: MARTINEZ | F37: ESLAVA | G37: 002846 | H37: MD SG PLACO & SG ISOVER & SG TRANSFORMADOS SPAIN | I37: J0041893 | K37: 002483 | L37: JEAN LUC | N37: GARDAZ | P37: . | T37: 58
A38: =INDEX('Orig (V1_BCK)'!$C:$C,MATCH($B38,'Orig (V1_BCK)'!$C:$C,0),1) -> #N/A | B38: =_xlfn.TEXTJOIN("-",FALSE,$C38,$I38,$J38) -> E8315205-A5895481- | C38: E8315205 | D38: ESTEFANIA | E38: FERNANDEZ | F38: BLANCO | G38: 000446 | H38: PLANT MANAGER AZUQUECA ISOVER | I38: A5895481 | K38: 002297 | L38: ANTONIO JOAQUIN | N38: RAMOS | P38: RAMOS | T38: 2G
A39: =INDEX('Orig (V1_BCK)'!$C:$C,MATCH($B39,'Orig (V1_BCK)'!$C:$C,0),1) -> F1158861-F1158861- | B39: =_xlfn.TEXTJOIN("-",FALSE,$C39,$I39,$J39) -> F1158861-F1158861- | C39: F1158861 | D39: FERNANDO | E39: GARCIA | F39: UBEDA | G39: 02577 | H39: PRODUCCIÓN (02577) | I39: F1158861 | K39: 148862 | L39: FERNANDO | N39: GARCIA | P39: UBEDA | T39: 58
A40: =INDEX('Orig (V1_BCK)'!$C:$C,MATCH($B40,'Orig (V1_BCK)'!$C:$C,0),1) -> F5049139-F5049139- | B40: =_xlfn.TEXTJOIN("-",FALSE,$C40,$I40,$J40) -> F5049139-F5049139- | C40: F5049139 | D40: FRANCISCO JAVIER | E40: DEL RIO | F40: ZAMANILLO | G40: 00580 | H40: RESPONSABLE SERV FABRICACIÓN (00580) | I40: F5049139 | K40: 001216 | L40: FRANCISCO JAVIER | N40: DEL RIO | P40: ZAMANILLO | T40: 05
...

Sheet Correg (V1)
A1: Coinciden con V1_BCK | C1: SGID | D1: Nombre | E1: Primer apellido | F1: Segundo apellido | G1: Unidad Org | H1: Nombre Unidad org | I1: SGID Resp Pos | J1: SGID Resp HR | K1: Unidad Org | L1: Nombre Resp Pos | M1: Nombre Resp HR | N1: Primer apellido Resp Pos | O1: Primer apellido Resp HR | P1: Segundo apellido Resp Pos | Q1: Segundo apellido Resp HR | R1: Record Type | S1: Box Sequence | T1: Empresa
A2: =INDEX('Orig (V1_BCK)'!$C:$C,MATCH($B2,'Orig (V1_BCK)'!$C:$C,0),1) -> A0702288-A0702288- | B2: =_xlfn.TEXTJOIN("-",FALSE,$C2,$I2,$J2) -> A0702288-A0702288- | C2: A0702288 | D2: AITOR | E2: SANTIBAÑEZ | F2: RODRIGUEZ | G2: 01244 | H2: PRODUCCIÓN (01244) | I2: A0702288 | K2: 139250 | L2: AITOR | N2: SANTIBAÑEZ | P2: RODRIGUEZ | T2: 58
A3: =INDEX('Orig (V1_BCK)'!$C:$C,MATCH($B3,'Orig (V1_BCK)'!$C:$C,0),1) -> #N/A | B3: =_xlfn.TEXTJOIN("-",FALSE,$C3,$I3,$J3) -> A0766752-- | C3: A0766752 | D3: ANDRES JUAN | E3: MORENO | F3: DE CAYEUX DE SENARPONT | G3: 03589 | H3: DIRECTOR ADM Y FINANCIERO (03589) | K3: PEND | T3: 1C
A4: =INDEX('Orig (V1_BCK)'!$C:$C,MATCH($B4,'Orig (V1_BCK)'!$C:$C,0),1) -> #N/A | B4: =_xlfn.TEXTJOIN("-",FALSE,$C4,$I4,$J4) -> A0835861-- | C4: A0835861 | D4: ALEJANDRO | E4: FERNANDEZ | F4: SUAREZ | G4: 03797 | H4: RESPONSABLE SERV FABRICACIÓN (03797) | K4: PEND | T4: 05
A5: =INDEX('Orig (V1_BCK)'!$C:$C,MATCH($B5,'Orig (V1_BCK)'!$C:$C,0),1) -> A1137670--G3229318 | B5: =_xlfn.TEXTJOIN("-",FALSE,$C5,$I5,$J5) -> A1137670--G3229318 | C5: A1137670 | D5: ANTONIO | E5: MARTINEZ | F5: ESCOLAR | G5: 03035 | H5: VENTAS (02283) | J5: G3229318 | K5: 01945 | M5: GREGORIO | O5: LASIERRA | Q5: LAPLANA | T5: 83
A6: =INDEX('Orig (V1_BCK)'!$C:$C,MATCH($B6,'Orig (V1_BCK)'!$C:$C,0),1) -> #N/A | B6: =_xlfn.TEXTJOIN("-",FALSE,$C6,$I6,$J6) -> A1203204-- | C6: A1203204 | D6: AICHA | E6: CHARLOT | F6: FARES | G6: 03017 | H6: JEFE VENTAS - OPERACIÓN DISTR (03017) | K6: PEND | T6: 62
A7: =INDEX('Orig (V1_BCK)'!$C:$C,MATCH($B7,'Orig (V1_BCK)'!$C:$C,0),1) -> A1692880-A1692880- | B7: =_xlfn.TEXTJOIN("-",FALSE,$C7,$I7,$J7) -> A1692880-A1692880- | C7: A1692880 | D7: ANTONIO | E7: CORRALES | F7: PULIDO | G7: 01275 | H7: PRODUCCIÓN (01275) | I7: A1692880 | K7: 003175 | L7: ANTONIO | N7: CORRALES | P7: PULIDO | T7: 2G
A8: =INDEX('Orig (V1_BCK)'!$C:$C,MATCH($B8,'Orig (V1_BCK)'!$C:$C,0),1) -> A1778775--I7600760 | B8: =_xlfn.TEXTJOIN("-",FALSE,$C8,$I8,$J8) -> A1778775--I7600760 | C8: A1778775 | D8: ANTONIO | E8: GALVEZ | F8: GONZALEZ | G8: 04609 | H8: 04609 | J8: I7600760 | K8: 02425 | M8: ISMAEL | O8: CIVIT | Q8: NOGUES | T8: 22
A9: =INDEX('Orig (V1_BCK)'!$C:$C,MATCH($B9,'Orig (V1_BCK)'!$C:$C,0),1) -> #N/A | B9: =_xlfn.TEXTJOIN("-",FALSE,$C9,$I9,$J9) -> A1894700-- | C9: A1894700 | D9: AFRICA | E9: ADAN | F9: ALONSO | G9: 03619 | H9: JEFE VENTAS - OPERACIÓN DISTR (03619) | K9: PEND | T9: 76
A10: =INDEX('Orig (V1_BCK)'!$C:$C,MATCH($B10,'Orig (V1_BCK)'!$C:$C,0),1) -> A1975872--J2161690 | B10: =_xlfn.TEXTJOIN("-",FALSE,$C10,$I10,$J10) -> A1975872--J2161690 | C10: A1975872 | D10: ANGEL | E10: GONZALEZ | F10: DIAZ | G10: 00618 | H10: 00868 (COMPRADOR LOCAL) | J10: J2161690 | K10: 00868 | M10: JUAN CARLOS | O10: RODRIGUEZ | Q10: ARMESTO | T10: 05
A11: =INDEX('Orig (V1_BCK)'!$C:$C,MATCH($B11,'Orig (V1_BCK)'!$C:$C,0),1) -> A2056971-A2056971- | B11: =_xlfn.TEXTJOIN("-",FALSE,$C11,$I11,$J11) -> A2056971-A2056971- | C11: A2056971 | D11: ALBERTO | E11: ANTON | F11: ESCRIBANO | G11: 04309 | H11: PRODUCCIÓN (04309) | I11: A2056971 | K11: 145420 | L11: ALBERTO | N11: ANTON | P11: ESCRIBANO | T11: 58
A12: =INDEX('Orig (V1_BCK)'!$C:$C,MATCH($B12,'Orig (V1_BCK)'!$C:$C,0),1) -> A2422013-A2422013- | B12: =_xlfn.TEXTJOIN("-",FALSE,$C12,$I12,$J12) -> A2422013-A2422013- | C12: A2422013 | D12: ALVARO | E12: BARRIO | F12: DELGADO | G12: 01180 | H12: JEFE DE ÁREA (01180) | I12: A2422013 | K12: 002283 | L12: ALVARO | N12: BARRIO | P12: DELGADO | T12: 22
A13: =INDEX('Orig (V1_BCK)'!$C:$C,MATCH($B13,'Orig (V1_BCK)'!$C:$C,0),1) -> A3127479-A3127479- | B13: =_xlfn.TEXTJOIN("-",FALSE,$C13,$I13,$J13) -> A3127479-A3127479- | C13: A3127479 | D13: ALBERTO | E13: MARTINEZ | F13: CARRAL | G13: 04199 | H13: PRODUCCIÓN (04199) | I13: A3127479 | K13: 002123 | L13: ALBERTO | N13: MARTINEZ | P13: CARRAL | T13: 71
A14: =INDEX('Orig (V1_BCK)'!$C:$C,MATCH($B14,'Orig (V1_BCK)'!$C:$C,0),1) -> #N/A | B14: =_xlfn.TEXTJOIN("-",FALSE,$C14,$I14,$J14) -> A3134550-- | C14: A3134550 | D14: ANGEL IGNACIO | E14: ARMENDARIZ | F14: VIGUERA | G14: 01239 | H14: SIN DEFINIR (01239) | K14: PEND | T14: 74
A15: =INDEX('Orig (V1_BCK)'!$C:$C,MATCH($B15,'Orig (V1_BCK)'!$C:$C,0),1) -> A3167958-A3167958- | B15: =_xlfn.TEXTJOIN("-",FALSE,$C15,$I15,$J15) -> A3167958-A3167958- | C15: A3167958 | D15: ANTONIO | E15: MORAL | F15: PEREZ | G15: 01730 | H15: JEFE DE ÁREA (01730) | I15: A3167958 | K15: 001778 | L15: ANTONIO | N15: MORAL | P15: PEREZ | T15: 22
A16: =INDEX('Orig (V1_BCK)'!$C:$C,MATCH($B16,'Orig (V1_BCK)'!$C:$C,0),1) -> A3258905-A3258905- | B16: =_xlfn.TEXTJOIN("-",FALSE,$C16,$I16,$J16) -> A3258905-A3258905- | C16: A3258905 | D16: ANGEL | E16: MARCILLA | F16: BASTIDA | G16: 02402 | H16: RESPONSABLE SERV FABRICACIÓN (02402) | I16: A3258905 | K16: 000601 | L16: ANGEL | N16: MARCILLA | P16: BASTIDA | T16: 05
A17: =INDEX('Orig (V1_BCK)'!$C:$C,MATCH($B17,'Orig (V1_BCK)'!$C:$C,0),1) -> A3284599-A3284599- | B17: =_xlfn.TEXTJOIN("-",FALSE,$C17,$I17,$J17) -> A3284599-A3284599- | C17: A3284599 | D17: ANGELICA | E17: GONZALO | F17: LOPEZ | G17: 03137 | H17: JEFE DE PRODUCTO (03137) | I17: A3284599 | K17: 000861 | L17: ANGELICA | N17: GONZALO | P17: LOPEZ | T17: 58
A18: =INDEX('Orig (V1_BCK)'!$C:$C,MATCH($B18,'Orig (V1_BCK)'!$C:$C,0),1) -> A3417212-A3417212- | B18: =_xlfn.TEXTJOIN("-",FALSE,$C18,$I18,$J18) -> A3417212-A3417212- | C18: A3417212 | D18: ALBERTO | E18: MARTINEZ | F18: DE PABLO | G18: 02437 | H18: RESPONSABLE LOGÍSTICA (02437) | I18: A3417212 | K18: 000701 | L18: ALBERTO | N18: MARTINEZ | P18: DE PABLO | T18: 05
A19: =INDEX('Orig (V1_BCK)'!$C:$C,MATCH($B19,'Orig (V1_BCK)'!$C:$C,0),1) -> A3485213-A3485213- | B19: =_xlfn.TEXTJOIN("-",FALSE,$C19,$I19,$J19) -> A3485213-A3485213- | C19: A3485213 | D19: AGUSTIN | E19: SUBIAS | F19: LIERTA | G19: 01589 | H19: PRODUCCIÓN (01589) | I19: A3485213 | K19: 139256 | L19: AGUSTIN | N19: SUBIAS | P19: LIERTA | T19: 58
A20: =INDEX('Orig (V1_BCK)'!$C:$C,MATCH($B20,'Orig (V1_BCK)'!$C:$C,0),1) -> A3575764--J6399199 | B20: =_xlfn.TEXTJOIN("-",FALSE,$C20,$I20,$J20) -> A3575764--J6399199 | C20: A3575764 | D20: ANTONIO | E20: VENDRELL | F20: VENDRELL | G20: 03363 | H20: SIN DEFINIR (03363) | J20: J6399199 | K20: 01878 | M20: JORDI | O20: ESTELLERS | Q20: CASTELLVI | T20: 22
A21: =INDEX('Orig (V1_BCK)'!$C:$C,MATCH($B21,'Orig (V1_BCK)'!$C:$C,0),1) -> #N/A | B21: =_xlfn.TEXTJOIN("-",FALSE,$C21,$I21,$J21) -> A4034881-- | C21: A4034881 | D21: ANA ISABEL | E21: MARTINEZ | F21: MARTINEZ | G21: 02554 | H21: JEFE VENTAS - OPERACIÓN DISTR (02554) | K21: PEND | T21: 62
A22: =INDEX('Orig (V1_BCK)'!$C:$C,MATCH($B22,'Orig (V1_BCK)'!$C:$C,0),1) -> #N/A | B22: =_xlfn.TEXTJOIN("-",FALSE,$C22,$I22,$J22) -> A4061325-- | C22: A4061325 | D22: AMADOR | E22: SABIO | F22: ORJALES | G22: 01805 | H22: RESPONSABLE DE ESTUDIOS MKG (01805) | K22: PEND | T22: 62
A23: =INDEX('Orig (V1_BCK)'!$C:$C,MATCH($B23,'Orig (V1_BCK)'!$C:$C,0),1) -> A4260911-A4260911- | B23: =_xlfn.TEXTJOIN("-",FALSE,$C23,$I23,$J23) -> A4260911-A4260911- | C23: A4260911 | D23: ADOLFO | E23: SOMOLINOS | F23: OREJON | G23: 03429 | H23: RESPONSABLE DE ESTUDIOS MKG (03429) | I23: A4260911 | K23: 003330 | L23: ADOLFO | N23: SOMOLINOS | P23: OREJON | T23: 58
A24: =INDEX('Orig (V1_BCK)'!$C:$C,MATCH($B24,'Orig (V1_BCK)'!$C:$C,0),1) -> A4544160--Y3223618 | B24: =_xlfn.TEXTJOIN("-",FALSE,$C24,$I24,$J24) -> A4544160--Y3223618 | C24: A4544160 | D24: ANTONIO | E24: TRUJILLO | F24: HELD | G24: 02480 | H24: 02480 | J24: Y3223618 | K24: 02655 | M24: YOLANDA | O24: PERALTA | Q24: ROSALEN | T24: 22
A25: =INDEX('Orig (V1_BCK)'!$C:$C,MATCH($B25,'Orig (V1_BCK)'!$C:$C,0),1) -> #N/A | B25: =_xlfn.TEXTJOIN("-",FALSE,$C25,$I25,$J25) -> A4598195-- | C25: A4598195 | D25: ALFREDO | E25: VILLA | F25: CELDRAN | G25: 02018 | H25: PRODUCCIÓN (02018) | K25: 001429 | T25: 05
A26: =INDEX('Orig (V1_BCK)'!$C:$C,MATCH($B26,'Orig (V1_BCK)'!$C:$C,0),1) -> #N/A | B26: =_xlfn.TEXTJOIN("-",FALSE,$C26,$I26,$J26) -> A4621755-- | C26: A4621755 | D26: ALBERTO | E26: PUAGO | F26: CRESPO | G26: 03238 | H26: WCM MANAGER (03238) | K26: PEND | T26: 58
A27: =INDEX('Orig (V1_BCK)'!$C:$C,MATCH($B27,'Orig (V1_BCK)'!$C:$C,0),1) -> A4769333--J1842217 | B27: =_xlfn.TEXTJOIN("-",FALSE,$C27,$I27,$J27) -> A4769333--J1842217 | C27: A4769333 | D27: ALEJANDRO | E27: RUIZ | F27: DURAN | G27: 03045 | H27: 01317 (JEFE DE ÁREA) | J27: J1842217 | K27: 01317 | M27: JUAN CARLOS | O27: ARRIBAS | Q27: RIAGUAS | T27: 22
A28: =INDEX('Orig (V1_BCK)'!$C:$C,MATCH($B28,'Orig (V1_BCK)'!$C:$C,0),1) -> #N/A | B28: =_xlfn.TEXTJOIN("-",FALSE,$C28,$I28,$J28) -> A5336853-- | C28: A5336853 | D28: ANTONIO | E28: PONSODA | F28: REINA | G28: 00242 | H28: PRODUCCIÓN (00242) | K28: 001685 | T28: 2G
A29: =INDEX('Orig (V1_BCK)'!$C:$C,MATCH($B29,'Orig (V1_BCK)'!$C:$C,0),1) -> A5358571-A5358571- | B29: =_xlfn.TEXTJOIN("-",FALSE,$C29,$I29,$J29) -> A5358571-A5358571- | C29: A5358571 | D29: ADRIAN | E29: PALACIO | F29: BEDIA | G29: 04193 | H29: PRODUCCIÓN (04193) | I29: A5358571 | K29: 002083 | L29: ADRIAN | N29: PALACIO | P29: BEDIA | T29: 71
A30: =INDEX('Orig (V1_BCK)'!$C:$C,MATCH($B30,'Orig (V1_BCK)'!$C:$C,0),1) -> #N/A | B30: =_xlfn.TEXTJOIN("-",FALSE,$C30,$I30,$J30) -> A5549694-- | C30: A5549694 | D30: ALEXANDRA | E30: HERNANDEZ | F30: BLANCO | G30: 01256 | H30: 01256 | K30: PEND | T30: 58
A31: =INDEX('Orig (V1_BCK)'!$C:$C,MATCH($B31,'Orig (V1_BCK)'!$C:$C,0),1) -> A5709653-A5709653- | B31: =_xlfn.TEXTJOIN("-",FALSE,$C31,$I31,$J31) -> A5709653-A5709653- | C31: A5709653 | D31: ANTONIO | E31: OLMO | F31: MELGAR | G31: 03407 | H31: PRODUCCIÓN (03407) | I31: A5709653 | K31: 139187 | L31: ANTONIO | N31: OLMO | P31: MELGAR | T31: 58
A32: =INDEX('Orig (V1_BCK)'!$C:$C,MATCH($B32,'Orig (V1_BCK)'!$C:$C,0),1) -> #N/A | B32: =_xlfn.TEXTJOIN("-",FALSE,$C32,$I32,$J32) -> A5743478-- | C32: A5743478 | D32: AGUSTIN | E32: MENDEZ | F32: LORENZO | G32: 02738 | H32: DTOR.ALMACÉN - OPERACIÓN DISTR (02738) | K32: PEND | T32: 62
A33: =INDEX('Orig (V1_BCK)'!$C:$C,MATCH($B33,'Orig (V1_BCK)'!$C:$C,0),1) -> #N/A | B33: =_xlfn.TEXTJOIN("-",FALSE,$C33,$I33,$J33) -> A5749070-- | C33: A5749070 | D33: AINHOA | E33: MACIA | F33: SUESCUN | G33: 01563 | H33: DIRECTOR DE COMUNICACIONES (01563) | K33: PEND | T33: 1J
A34: =INDEX('Orig (V1_BCK)'!$C:$C,MATCH($B34,'Orig (V1_BCK)'!$C:$C,0),1) -> #N/A | B34: =_xlfn.TEXTJOIN("-",FALSE,$C34,$I34,$J34) -> A5895481-- | C34: A5895481 | D34: ANTONIO JOAQUIN | E34: RAMOS | F34: RAMOS | G34: 01653 | H34: DIRECTOR DE DIVISIÓN (01653) | K34: PEND | T34: 58
A35: =INDEX('Orig (V1_BCK)'!$C:$C,MATCH($B35,'Orig (V1_BCK)'!$C:$C,0),1) -> #N/A | B35: =_xlfn.TEXTJOIN("-",FALSE,$C35,$I35,$J35) -> A6120271-- | C35: A6120271 | D35: ANA ISABEL | E35: PANDIELLA | F35: HEVIA | G35: 03505 | H35: SIN DEFINIR (03505) | K35: PEND | T35: 05
A36: =INDEX('Orig (V1_BCK)'!$C:$C,MATCH($B36,'Orig (V1_BCK)'!$C:$C,0),1) -> #N/A | B36: =_xlfn.TEXTJOIN("-",FALSE,$C36,$I36,$J36) -> A6396628-- | C36: A6396628 | D36: ANTONIO | E36: MADERA | F36: GARCIA | G36: 01622 | H36: MARKETING (01622) | K36: PEND | T36: 15
A37: =INDEX('Orig (V1_BCK)'!$C:$C,MATCH($B37,'Orig (V1_BCK)'!$C:$C,0),1) -> A6553191--F7796330 | B37: =_xlfn.TEXTJOIN("-",FALSE,$C37,$I37,$J37) -> A6553191--F7796330 | C37: A6553191 | D37: ANTONIO M. | E37: DE LA FUENTE | F37: GUTIERREZ | G37: 04219 | H37: PRODUCCIÓN (04219) | J37: F7796330 | K37: 01040 | M37: FRANCISCO JAVIER | O37: BRAVO | Q37: SARO | T37: 71
A38: =INDEX('Orig (V1_BCK)'!$C:$C,MATCH($B38,'Orig (V1_BCK)'!$C:$C,0),1) -> A6556153-A6556153- | B38: =_xlfn.TEXTJOIN("-",FALSE,$C38,$I38,$J38) -> A6556153-A6556153- | C38: A6556153 | D38: ANTONIO MOISES | E38: SANTOS | F38: AVELLANO | G38: 03662 | H38: OPERACIONES DISTRIBUCIÓN (03363) | I38: A6556153 | K38: 002583 | L38: ANTONIO MOISES | N38: SANTOS | P38: AVELLANO | T38: 62
A39: =INDEX('Orig (V1_BCK)'!$C:$C,MATCH($B39,'Orig (V1_BCK)'!$C:$C,0),1) -> #N/A | B39: =_xlfn.TEXTJOIN("-",FALSE,$C39,$I39,$J39) -> A6570134-- | C39: A6570134 | D39: ANTONIO | E39: BASCONES | F39: PARAMIO | G39: 00585 | H39: RESPONSABLE LOGÍSTICA (00585) | K39: PEND | T39: 05
A40: =INDEX('Orig (V1_BCK)'!$C:$C,MATCH($B40,'Orig (V1_BCK)'!$C:$C,0),1) -> A6653585-A6653585- | B40: =_xlfn.TEXTJOIN("-",FALSE,$C40,$I40,$J40) -> A6653585-A6653585- | C40: A6653585 | D40: ANTONIO | E40: LUNA | F40: LIBRERO | G40: 01662 | H40: DIRECTOR DE FÁBRICA (01662) | I40: A6653585 | K40: 000950 | L40: ANTONIO | N40: LUNA | P40: LIBRERO | T40: 58
...

Sheet Leyendas
A1: El empleado RESPONSABLE tiene el histórico POSICIÓN CERRADO en fechas FUERA del periodo actual
A2: No se ha obtenido el SGID del empleado en CONSULTA ORIGINAL
A3: El empleado RESPONSABLE tiene histórico POSICIÓN VÁLIDO en fechas DENTRO del periodo actual
A4: El empleado RESPONSABLE tiene histórico POSICIÓN CERRADO en fechas FUERA del periodo actual
